{"name": "test_muti_assert", "status": "failed", "statusDetails": {"message": "AssertionError: assert 3 == 4\n  +3\n  -4", "trace": "def test_muti_assert():\n>       assert add(1,2) == random.randint(3,10)\nE       assert 3 == 4\nE         +3\nE         -4\n\ntest_rerunfailures.py:8: AssertionError"}, "start": 1597110653759, "stop": 1597110653759, "uuid": "9ead3be4-9e32-4308-94c4-cc900ce67562", "historyId": "4e47d298baa5359e34dbf96377232db8", "testCaseId": "07be5f4a1a68e890aa41e8064ae1971c", "fullName": "test_rerunfailures#test_muti_assert", "labels": [{"name": "suite", "value": "test_rerunfailures"}, {"name": "host", "value": "user-PC"}, {"name": "thread", "value": "18200-MainThread"}, {"name": "framework", "value": "pytest"}, {"name": "language", "value": "cpython3"}, {"name": "package", "value": "test_rerunfailures"}]}