{"name": "test_muti_assert", "status": "failed", "statusDetails": {"message": "AssertionError: assert 3 == 5\n  +3\n  -5", "trace": "def test_muti_assert():\n>       assert add(1,2) == random.randint(3,10)\nE       assert 3 == 5\nE         +3\nE         -5\n\ntest_rerunfailures.py:8: AssertionError"}, "start": 1596104133540, "stop": 1596104133540, "uuid": "70e88765-97d6-46b1-88c7-52b1addc35e0", "historyId": "4e47d298baa5359e34dbf96377232db8", "testCaseId": "07be5f4a1a68e890aa41e8064ae1971c", "fullName": "test_rerunfailures#test_muti_assert", "labels": [{"name": "suite", "value": "test_rerunfailures"}, {"name": "host", "value": "user-PC"}, {"name": "thread", "value": "15028-MainThread"}, {"name": "framework", "value": "pytest"}, {"name": "language", "value": "cpython3"}, {"name": "package", "value": "test_rerunfailures"}]}